<?xml version="0.0" ?>
<robot name="">
	<link name="link0">
		<inertial>
			<origin rpy="0.00000 -0.00000 0.00000" xyz="0.00000 0.00000 0.00000"/>
			<mass value="1000000000.00000"/>
			<inertia ixx="560863.43222" ixy="0" ixz="0" iyy="706841.20624" iyz="0" izz="502031.37623"/>
		</inertial>
		<visual>
			<origin rpy="0.00000 -0.00000 0.00000" xyz="0.00000 0.00000 0.00000"/>
			<geometry>
				<box size="0.06235 0.04622 0.06778"/>
			</geometry>
			<material name="mat_-1_0">
				<color rgba="1.00000 1.00000 1.00000 1.00000" />
			</material>
		</visual>
		<collision>
			<origin rpy="0.00000 -0.00000 0.00000" xyz="0.00000 0.00000 0.00000"/>
			<geometry>
				<box size="0.06235 0.04622 0.06778"/>
			</geometry>
		</collision>
	</link>
	<link name="link1">
		<inertial>
			<origin rpy="0.00000 -0.00000 0.00000" xyz="0.00000 0.00000 0.00000"/>
			<mass value="0.00000"/>
			<inertia ixx="0.00000" ixy="0" ixz="0" iyy="0.00000" iyz="0" izz="0.00000"/>
		</inertial>
		<visual>
			<origin rpy="0.00000 -0.00000 0.00000" xyz="0.00000 0.00000 0.00000"/>
			<geometry>
				<box size="0.00000 0.00000 0.00000"/>
			</geometry>
			<material name="mat_0_0">
				<color rgba="1.00000 1.00000 1.00000 1.00000" />
			</material>
		</visual>
		<collision>
			<origin rpy="0.00000 -0.00000 0.00000" xyz="0.00000 0.00000 0.00000"/>
			<geometry>
				<box size="0.00000 0.00000 0.00000"/>
			</geometry>
		</collision>
	</link>
	<link name="link2">
		<inertial>
			<origin rpy="0.00000 -0.00000 0.00000" xyz="0.00000 0.00000 0.25000"/>
			<mass value="10.00000"/>
			<inertia ixx="0.19740" ixy="0" ixz="0" iyy="0.19740" iyz="0" izz="0.00417"/>
		</inertial>
		<visual>
			<origin rpy="0.00000 -0.00000 0.00000" xyz="0.00000 0.00000 0.29206"/>
			<geometry>
				<box size="0.05000 0.05000 0.48413"/>
			</geometry>
			<material name="mat_1_0">
				<color rgba="1.00000 1.00000 1.00000 1.00000" />
			</material>
		</visual>
		<collision>
			<origin rpy="0.00000 -0.00000 0.00000" xyz="0.00000 0.00000 0.29206"/>
			<geometry>
				<box size="0.05000 0.05000 0.48413"/>
			</geometry>
		</collision>
	</link>
	<link name="link3">
		<inertial>
			<origin rpy="0.00000 -0.00000 0.00000" xyz="0.00000 0.00000 0.00000"/>
			<mass value="0.00000"/>
			<inertia ixx="0.00000" ixy="0" ixz="0" iyy="0.00000" iyz="0" izz="0.00000"/>
		</inertial>
		<visual>
			<origin rpy="0.00000 -0.00000 0.00000" xyz="0.00000 0.00000 0.00000"/>
			<geometry>
				<box size="0.00000 0.00000 0.00000"/>
			</geometry>
			<material name="mat_2_0">
				<color rgba="1.00000 1.00000 1.00000 1.00000" />
			</material>
		</visual>
		<collision>
			<origin rpy="0.00000 -0.00000 0.00000" xyz="0.00000 0.00000 0.00000"/>
			<geometry>
				<box size="0.00000 0.00000 0.00000"/>
			</geometry>
		</collision>
	</link>
	<link name="link4">
		<inertial>
			<origin rpy="0.00000 -0.00000 0.00000" xyz="0.00000 0.00000 0.25000"/>
			<mass value="10.00000"/>
			<inertia ixx="0.18301" ixy="0" ixz="0" iyy="0.18301" iyz="0" izz="0.00417"/>
		</inertial>
		<visual>
			<origin rpy="0.00000 -0.00000 0.00000" xyz="0.00000 0.00000 0.28298"/>
			<geometry>
				<box size="0.05000 0.05000 0.46595"/>
			</geometry>
			<material name="mat_3_0">
				<color rgba="1.00000 1.00000 1.00000 1.00000" />
			</material>
		</visual>
		<collision>
			<origin rpy="0.00000 -0.00000 0.00000" xyz="0.00000 0.00000 0.28298"/>
			<geometry>
				<box size="0.05000 0.05000 0.46595"/>
			</geometry>
		</collision>
	</link>
	<link name="link5">
		<inertial>
			<origin rpy="0.00000 -0.00000 0.00000" xyz="0.00000 0.00000 0.00000"/>
			<mass value="0.00000"/>
			<inertia ixx="0.00000" ixy="0" ixz="0" iyy="0.00000" iyz="0" izz="0.00000"/>
		</inertial>
		<visual>
			<origin rpy="0.00000 -0.00000 0.00000" xyz="0.00000 0.00000 0.00000"/>
			<geometry>
				<box size="0.00000 0.00000 0.00000"/>
			</geometry>
			<material name="mat_4_0">
				<color rgba="1.00000 1.00000 1.00000 1.00000" />
			</material>
		</visual>
		<collision>
			<origin rpy="0.00000 -0.00000 0.00000" xyz="0.00000 0.00000 0.00000"/>
			<geometry>
				<box size="0.00000 0.00000 0.00000"/>
			</geometry>
		</collision>
	</link>
	<link name="link6">
		<inertial>
			<origin rpy="0.00000 -0.00000 0.00000" xyz="0.00000 0.00000 0.25000"/>
			<mass value="10.00000"/>
			<inertia ixx="0.15955" ixy="0" ixz="0" iyy="0.15955" iyz="0" izz="0.00417"/>
		</inertial>
		<visual>
			<origin rpy="0.00000 -0.00000 0.00000" xyz="0.00000 0.00000 0.26735"/>
			<geometry>
				<box size="0.05000 0.05000 0.43470"/>
			</geometry>
			<material name="mat_5_0">
				<color rgba="1.00000 1.00000 1.00000 1.00000" />
			</material>
		</visual>
		<collision>
			<origin rpy="0.00000 -0.00000 0.00000" xyz="0.00000 0.00000 0.26735"/>
			<geometry>
				<box size="0.05000 0.05000 0.43470"/>
			</geometry>
		</collision>
	</link>
	<link name="link7">
		<inertial>
			<origin rpy="0.00000 -0.00000 0.00000" xyz="0.00000 0.00000 0.00000"/>
			<mass value="0.00000"/>
			<inertia ixx="0.00000" ixy="0" ixz="0" iyy="0.00000" iyz="0" izz="0.00000"/>
		</inertial>
		<visual>
			<origin rpy="0.00000 -0.00000 0.00000" xyz="0.00000 0.00000 0.00000"/>
			<geometry>
				<box size="0.00000 0.00000 0.00000"/>
			</geometry>
			<material name="mat_6_0">
				<color rgba="1.00000 1.00000 1.00000 1.00000" />
			</material>
		</visual>
		<collision>
			<origin rpy="0.00000 -0.00000 0.00000" xyz="0.00000 0.00000 0.00000"/>
			<geometry>
				<box size="0.00000 0.00000 0.00000"/>
			</geometry>
		</collision>
	</link>
	<link name="link8">
		<inertial>
			<origin rpy="0.00000 -0.00000 0.00000" xyz="0.00000 0.00000 0.25000"/>
			<mass value="10.00000"/>
			<inertia ixx="0.13564" ixy="0" ixz="0" iyy="0.13564" iyz="0" izz="0.00417"/>
		</inertial>
		<visual>
			<origin rpy="0.00000 -0.00000 0.00000" xyz="0.00000 0.00000 0.25017"/>
			<geometry>
				<box size="0.05000 0.05000 0.40034"/>
			</geometry>
			<material name="mat_7_0">
				<color rgba="1.00000 1.00000 1.00000 1.00000" />
			</material>
		</visual>
		<collision>
			<origin rpy="0.00000 -0.00000 0.00000" xyz="0.00000 0.00000 0.25017"/>
			<geometry>
				<box size="0.05000 0.05000 0.40034"/>
			</geometry>
		</collision>
	</link>
	<link name="link9">
		<inertial>
			<origin rpy="0.00000 -0.00000 0.00000" xyz="0.00000 0.00000 0.00000"/>
			<mass value="0.00000"/>
			<inertia ixx="0.00000" ixy="0" ixz="0" iyy="0.00000" iyz="0" izz="0.00000"/>
		</inertial>
		<visual>
			<origin rpy="0.00000 -0.00000 0.00000" xyz="0.00000 0.00000 0.00000"/>
			<geometry>
				<box size="0.00000 0.00000 0.00000"/>
			</geometry>
			<material name="mat_8_0">
				<color rgba="1.00000 1.00000 1.00000 1.00000" />
			</material>
		</visual>
		<collision>
			<origin rpy="0.00000 -0.00000 0.00000" xyz="0.00000 0.00000 0.00000"/>
			<geometry>
				<box size="0.00000 0.00000 0.00000"/>
			</geometry>
		</collision>
	</link>
	<link name="link10">
		<inertial>
			<origin rpy="0.00000 -0.00000 0.00000" xyz="0.00000 0.00000 0.25000"/>
			<mass value="10.00000"/>
			<inertia ixx="0.15504" ixy="0" ixz="0" iyy="0.15504" iyz="0" izz="0.00417"/>
		</inertial>
		<visual>
			<origin rpy="0.00000 -0.00000 0.00000" xyz="0.00000 0.00000 0.26421"/>
			<geometry>
				<box size="0.05000 0.05000 0.42842"/>
			</geometry>
			<material name="mat_9_0">
				<color rgba="1.00000 1.00000 1.00000 1.00000" />
			</material>
		</visual>
		<collision>
			<origin rpy="0.00000 -0.00000 0.00000" xyz="0.00000 0.00000 0.26421"/>
			<geometry>
				<box size="0.05000 0.05000 0.42842"/>
			</geometry>
		</collision>
	</link>
	<joint name="joint1" type="continuous">
		<parent link="link0"/>
		<child link="link1"/>
		<dynamics damping="1.0" friction="0.0001"/>
		<origin rpy="0.00000 -0.00000 0.00000" xyz="0.00000 0.00000 0.03389"/>
		<axis xyz="1.00000 0.00000 0.00000"/>
	</joint>
	<joint name="joint2" type="continuous">
		<parent link="link1"/>
		<child link="link2"/>
		<dynamics damping="1.0" friction="0.0001"/>
		<origin rpy="0.00000 -0.00000 0.00000" xyz="0.00000 0.00000 0.00000"/>
		<axis xyz="0.00000 1.00000 0.00000"/>
	</joint>
	<joint name="joint3" type="continuous">
		<parent link="link2"/>
		<child link="link3"/>
		<dynamics damping="1.0" friction="0.0001"/>
		<origin rpy="0.00000 1.13291 -0.20771" xyz="0.05000 0.01234 0.41960"/>
		<axis xyz="1.00000 0.00000 0.00000"/>
	</joint>
	<joint name="joint4" type="continuous">
		<parent link="link3"/>
		<child link="link4"/>
		<dynamics damping="1.0" friction="0.0001"/>
		<origin rpy="0.00000 -0.00000 0.00000" xyz="0.00000 0.00000 0.00000"/>
		<axis xyz="0.00000 1.00000 0.00000"/>
	</joint>
	<joint name="joint5" type="continuous">
		<parent link="link4"/>
		<child link="link5"/>
		<dynamics damping="1.0" friction="0.0001"/>
		<origin rpy="0.02898 -0.00000 0.00000" xyz="0.00000 0.00000 0.51595"/>
		<axis xyz="1.00000 0.00000 0.00000"/>
	</joint>
	<joint name="joint6" type="continuous">
		<parent link="link5"/>
		<child link="link6"/>
		<dynamics damping="1.0" friction="0.0001"/>
		<origin rpy="0.00000 -0.00000 0.00000" xyz="0.00000 0.00000 0.00000"/>
		<axis xyz="0.00000 1.00000 0.00000"/>
	</joint>
	<joint name="joint7" type="continuous">
		<parent link="link2"/>
		<child link="link7"/>
		<dynamics damping="1.0" friction="0.0001"/>
		<origin rpy="0.70461 0.00000 -0.33652" xyz="0.01642 -0.05000 0.34064"/>
		<axis xyz="1.00000 0.00000 0.00000"/>
	</joint>
	<joint name="joint8" type="continuous">
		<parent link="link7"/>
		<child link="link8"/>
		<dynamics damping="1.0" friction="0.0001"/>
		<origin rpy="0.00000 -0.00000 0.00000" xyz="0.00000 0.00000 0.00000"/>
		<axis xyz="0.00000 1.00000 0.00000"/>
	</joint>
	<joint name="joint9" type="continuous">
		<parent link="link8"/>
		<child link="link9"/>
		<dynamics damping="1.0" friction="0.0001"/>
		<origin rpy="0.10992 -0.00000 0.00000" xyz="0.00000 0.00000 0.45034"/>
		<axis xyz="1.00000 0.00000 0.00000"/>
	</joint>
	<joint name="joint10" type="continuous">
		<parent link="link9"/>
		<child link="link10"/>
		<dynamics damping="1.0" friction="0.0001"/>
		<origin rpy="0.00000 -0.00000 0.00000" xyz="0.00000 0.00000 0.00000"/>
		<axis xyz="0.00000 1.00000 0.00000"/>
	</joint>
</robot>
