<?xml version="0.0" ?>
<robot name="">
	<link name="link0">
		<inertial>
			<origin rpy="0.00000 -0.00000 0.00000" xyz="0.00000 0.00000 0.00000"/>
			<mass value="1000000000.00000"/>
			<inertia ixx="262247.92589" ixy="0" ixz="0" iyy="457220.09429" iyz="0" izz="482881.29348"/>
		</inertial>
		<visual>
			<origin rpy="0.00000 -0.00000 0.00000" xyz="0.00000 0.00000 0.00000"/>
			<geometry>
				<box size="0.06377 0.04156 0.03768"/>
			</geometry>
			<material name="mat_-1_0">
				<color rgba="1.00000 1.00000 1.00000 1.00000" />
			</material>
		</visual>
		<collision>
			<origin rpy="0.00000 -0.00000 0.00000" xyz="0.00000 0.00000 0.00000"/>
			<geometry>
				<box size="0.06377 0.04156 0.03768"/>
			</geometry>
		</collision>
	</link>
	<link name="link1">
		<inertial>
			<origin rpy="0.00000 -0.00000 0.00000" xyz="0.00000 0.00000 0.00000"/>
			<mass value="0.00000"/>
			<inertia ixx="0.00000" ixy="0" ixz="0" iyy="0.00000" iyz="0" izz="0.00000"/>
		</inertial>
		<visual>
			<origin rpy="0.00000 -0.00000 0.00000" xyz="0.00000 0.00000 0.00000"/>
			<geometry>
				<box size="0.00000 0.00000 0.00000"/>
			</geometry>
			<material name="mat_0_0">
				<color rgba="1.00000 1.00000 1.00000 1.00000" />
			</material>
		</visual>
		<collision>
			<origin rpy="0.00000 -0.00000 0.00000" xyz="0.00000 0.00000 0.00000"/>
			<geometry>
				<box size="0.00000 0.00000 0.00000"/>
			</geometry>
		</collision>
	</link>
	<link name="link2">
		<inertial>
			<origin rpy="0.00000 -0.00000 0.00000" xyz="0.00000 0.00000 0.25000"/>
			<mass value="10.00000"/>
			<inertia ixx="0.15815" ixy="0" ixz="0" iyy="0.15815" iyz="0" izz="0.00417"/>
		</inertial>
		<visual>
			<origin rpy="0.00000 -0.00000 0.00000" xyz="0.00000 0.00000 0.24138"/>
			<geometry>
				<box size="0.05000 0.05000 0.43276"/>
			</geometry>
			<material name="mat_1_0">
				<color rgba="1.00000 1.00000 1.00000 1.00000" />
			</material>
		</visual>
		<collision>
			<origin rpy="0.00000 -0.00000 0.00000" xyz="0.00000 0.00000 0.24138"/>
			<geometry>
				<box size="0.05000 0.05000 0.43276"/>
			</geometry>
		</collision>
	</link>
	<link name="link3">
		<inertial>
			<origin rpy="0.00000 -0.00000 0.00000" xyz="0.00000 0.00000 0.00000"/>
			<mass value="0.00000"/>
			<inertia ixx="0.00000" ixy="0" ixz="0" iyy="0.00000" iyz="0" izz="0.00000"/>
		</inertial>
		<visual>
			<origin rpy="0.00000 -0.00000 0.00000" xyz="0.00000 0.00000 0.00000"/>
			<geometry>
				<box size="0.00000 0.00000 0.00000"/>
			</geometry>
			<material name="mat_2_0">
				<color rgba="1.00000 1.00000 1.00000 1.00000" />
			</material>
		</visual>
		<collision>
			<origin rpy="0.00000 -0.00000 0.00000" xyz="0.00000 0.00000 0.00000"/>
			<geometry>
				<box size="0.00000 0.00000 0.00000"/>
			</geometry>
		</collision>
	</link>
	<link name="link4">
		<inertial>
			<origin rpy="0.00000 -0.00000 0.00000" xyz="0.00000 0.00000 0.25000"/>
			<mass value="10.00000"/>
			<inertia ixx="0.15173" ixy="0" ixz="0" iyy="0.15173" iyz="0" izz="0.00417"/>
		</inertial>
		<visual>
			<origin rpy="0.00000 -0.00000 0.00000" xyz="0.00000 0.00000 0.23688"/>
			<geometry>
				<box size="0.05000 0.05000 0.42377"/>
			</geometry>
			<material name="mat_3_0">
				<color rgba="1.00000 1.00000 1.00000 1.00000" />
			</material>
		</visual>
		<collision>
			<origin rpy="0.00000 -0.00000 0.00000" xyz="0.00000 0.00000 0.23688"/>
			<geometry>
				<box size="0.05000 0.05000 0.42377"/>
			</geometry>
		</collision>
	</link>
	<link name="link5">
		<inertial>
			<origin rpy="0.00000 -0.00000 0.00000" xyz="0.00000 0.00000 0.00000"/>
			<mass value="0.00000"/>
			<inertia ixx="0.00000" ixy="0" ixz="0" iyy="0.00000" iyz="0" izz="0.00000"/>
		</inertial>
		<visual>
			<origin rpy="0.00000 -0.00000 0.00000" xyz="0.00000 0.00000 0.00000"/>
			<geometry>
				<box size="0.00000 0.00000 0.00000"/>
			</geometry>
			<material name="mat_4_0">
				<color rgba="1.00000 1.00000 1.00000 1.00000" />
			</material>
		</visual>
		<collision>
			<origin rpy="0.00000 -0.00000 0.00000" xyz="0.00000 0.00000 0.00000"/>
			<geometry>
				<box size="0.00000 0.00000 0.00000"/>
			</geometry>
		</collision>
	</link>
	<link name="link6">
		<inertial>
			<origin rpy="0.00000 -0.00000 0.00000" xyz="0.00000 0.00000 0.25000"/>
			<mass value="10.00000"/>
			<inertia ixx="0.17983" ixy="0" ixz="0" iyy="0.17983" iyz="0" izz="0.00417"/>
		</inertial>
		<visual>
			<origin rpy="0.00000 -0.00000 0.00000" xyz="0.00000 0.00000 0.25592"/>
			<geometry>
				<box size="0.05000 0.05000 0.46184"/>
			</geometry>
			<material name="mat_5_0">
				<color rgba="1.00000 1.00000 1.00000 1.00000" />
			</material>
		</visual>
		<collision>
			<origin rpy="0.00000 -0.00000 0.00000" xyz="0.00000 0.00000 0.25592"/>
			<geometry>
				<box size="0.05000 0.05000 0.46184"/>
			</geometry>
		</collision>
	</link>
	<link name="link7">
		<inertial>
			<origin rpy="0.00000 -0.00000 0.00000" xyz="0.00000 0.00000 0.00000"/>
			<mass value="0.00000"/>
			<inertia ixx="0.00000" ixy="0" ixz="0" iyy="0.00000" iyz="0" izz="0.00000"/>
		</inertial>
		<visual>
			<origin rpy="0.00000 -0.00000 0.00000" xyz="0.00000 0.00000 0.00000"/>
			<geometry>
				<box size="0.00000 0.00000 0.00000"/>
			</geometry>
			<material name="mat_6_0">
				<color rgba="1.00000 1.00000 1.00000 1.00000" />
			</material>
		</visual>
		<collision>
			<origin rpy="0.00000 -0.00000 0.00000" xyz="0.00000 0.00000 0.00000"/>
			<geometry>
				<box size="0.00000 0.00000 0.00000"/>
			</geometry>
		</collision>
	</link>
	<link name="link8">
		<inertial>
			<origin rpy="0.00000 -0.00000 0.00000" xyz="0.00000 0.00000 0.25000"/>
			<mass value="10.00000"/>
			<inertia ixx="0.17821" ixy="0" ixz="0" iyy="0.17821" iyz="0" izz="0.00417"/>
		</inertial>
		<visual>
			<origin rpy="0.00000 -0.00000 0.00000" xyz="0.00000 0.00000 0.25486"/>
			<geometry>
				<box size="0.05000 0.05000 0.45973"/>
			</geometry>
			<material name="mat_7_0">
				<color rgba="1.00000 1.00000 1.00000 1.00000" />
			</material>
		</visual>
		<collision>
			<origin rpy="0.00000 -0.00000 0.00000" xyz="0.00000 0.00000 0.25486"/>
			<geometry>
				<box size="0.05000 0.05000 0.45973"/>
			</geometry>
		</collision>
	</link>
	<link name="link9">
		<inertial>
			<origin rpy="0.00000 -0.00000 0.00000" xyz="0.00000 0.00000 0.00000"/>
			<mass value="0.00000"/>
			<inertia ixx="0.00000" ixy="0" ixz="0" iyy="0.00000" iyz="0" izz="0.00000"/>
		</inertial>
		<visual>
			<origin rpy="0.00000 -0.00000 0.00000" xyz="0.00000 0.00000 0.00000"/>
			<geometry>
				<box size="0.00000 0.00000 0.00000"/>
			</geometry>
			<material name="mat_8_0">
				<color rgba="1.00000 1.00000 1.00000 1.00000" />
			</material>
		</visual>
		<collision>
			<origin rpy="0.00000 -0.00000 0.00000" xyz="0.00000 0.00000 0.00000"/>
			<geometry>
				<box size="0.00000 0.00000 0.00000"/>
			</geometry>
		</collision>
	</link>
	<link name="link10">
		<inertial>
			<origin rpy="0.00000 -0.00000 0.00000" xyz="0.00000 0.00000 0.25000"/>
			<mass value="10.00000"/>
			<inertia ixx="0.12719" ixy="0" ixz="0" iyy="0.12719" iyz="0" izz="0.00417"/>
		</inertial>
		<visual>
			<origin rpy="0.00000 -0.00000 0.00000" xyz="0.00000 0.00000 0.21873"/>
			<geometry>
				<box size="0.05000 0.05000 0.38746"/>
			</geometry>
			<material name="mat_9_0">
				<color rgba="1.00000 1.00000 1.00000 1.00000" />
			</material>
		</visual>
		<collision>
			<origin rpy="0.00000 -0.00000 0.00000" xyz="0.00000 0.00000 0.21873"/>
			<geometry>
				<box size="0.05000 0.05000 0.38746"/>
			</geometry>
		</collision>
	</link>
	<link name="link11">
		<inertial>
			<origin rpy="0.00000 -0.00000 0.00000" xyz="0.00000 0.00000 0.00000"/>
			<mass value="0.00000"/>
			<inertia ixx="0.00000" ixy="0" ixz="0" iyy="0.00000" iyz="0" izz="0.00000"/>
		</inertial>
		<visual>
			<origin rpy="0.00000 -0.00000 0.00000" xyz="0.00000 0.00000 0.00000"/>
			<geometry>
				<box size="0.00000 0.00000 0.00000"/>
			</geometry>
			<material name="mat_10_0">
				<color rgba="1.00000 1.00000 1.00000 1.00000" />
			</material>
		</visual>
		<collision>
			<origin rpy="0.00000 -0.00000 0.00000" xyz="0.00000 0.00000 0.00000"/>
			<geometry>
				<box size="0.00000 0.00000 0.00000"/>
			</geometry>
		</collision>
	</link>
	<link name="link12">
		<inertial>
			<origin rpy="0.00000 -0.00000 0.00000" xyz="0.00000 0.00000 0.25000"/>
			<mass value="10.00000"/>
			<inertia ixx="0.16026" ixy="0" ixz="0" iyy="0.16026" iyz="0" izz="0.00417"/>
		</inertial>
		<visual>
			<origin rpy="0.00000 -0.00000 0.00000" xyz="0.00000 0.00000 0.24284"/>
			<geometry>
				<box size="0.05000 0.05000 0.43568"/>
			</geometry>
			<material name="mat_11_0">
				<color rgba="1.00000 1.00000 1.00000 1.00000" />
			</material>
		</visual>
		<collision>
			<origin rpy="0.00000 -0.00000 0.00000" xyz="0.00000 0.00000 0.24284"/>
			<geometry>
				<box size="0.05000 0.05000 0.43568"/>
			</geometry>
		</collision>
	</link>
	<link name="link13">
		<inertial>
			<origin rpy="0.00000 -0.00000 0.00000" xyz="0.00000 0.00000 0.00000"/>
			<mass value="0.00000"/>
			<inertia ixx="0.00000" ixy="0" ixz="0" iyy="0.00000" iyz="0" izz="0.00000"/>
		</inertial>
		<visual>
			<origin rpy="0.00000 -0.00000 0.00000" xyz="0.00000 0.00000 0.00000"/>
			<geometry>
				<box size="0.00000 0.00000 0.00000"/>
			</geometry>
			<material name="mat_12_0">
				<color rgba="1.00000 1.00000 1.00000 1.00000" />
			</material>
		</visual>
		<collision>
			<origin rpy="0.00000 -0.00000 0.00000" xyz="0.00000 0.00000 0.00000"/>
			<geometry>
				<box size="0.00000 0.00000 0.00000"/>
			</geometry>
		</collision>
	</link>
	<link name="link14">
		<inertial>
			<origin rpy="0.00000 -0.00000 0.00000" xyz="0.00000 0.00000 0.25000"/>
			<mass value="10.00000"/>
			<inertia ixx="0.11160" ixy="0" ixz="0" iyy="0.11160" iyz="0" izz="0.00417"/>
		</inertial>
		<visual>
			<origin rpy="0.00000 -0.00000 0.00000" xyz="0.00000 0.00000 0.20626"/>
			<geometry>
				<box size="0.05000 0.05000 0.36251"/>
			</geometry>
			<material name="mat_13_0">
				<color rgba="1.00000 1.00000 1.00000 1.00000" />
			</material>
		</visual>
		<collision>
			<origin rpy="0.00000 -0.00000 0.00000" xyz="0.00000 0.00000 0.20626"/>
			<geometry>
				<box size="0.05000 0.05000 0.36251"/>
			</geometry>
		</collision>
	</link>
	<link name="link15">
		<inertial>
			<origin rpy="0.00000 -0.00000 0.00000" xyz="0.00000 0.00000 0.00000"/>
			<mass value="0.00000"/>
			<inertia ixx="0.00000" ixy="0" ixz="0" iyy="0.00000" iyz="0" izz="0.00000"/>
		</inertial>
		<visual>
			<origin rpy="0.00000 -0.00000 0.00000" xyz="0.00000 0.00000 0.00000"/>
			<geometry>
				<box size="0.00000 0.00000 0.00000"/>
			</geometry>
			<material name="mat_14_0">
				<color rgba="1.00000 1.00000 1.00000 1.00000" />
			</material>
		</visual>
		<collision>
			<origin rpy="0.00000 -0.00000 0.00000" xyz="0.00000 0.00000 0.00000"/>
			<geometry>
				<box size="0.00000 0.00000 0.00000"/>
			</geometry>
		</collision>
	</link>
	<link name="link16">
		<inertial>
			<origin rpy="0.00000 -0.00000 0.00000" xyz="0.00000 0.00000 0.25000"/>
			<mass value="10.00000"/>
			<inertia ixx="0.17499" ixy="0" ixz="0" iyy="0.17499" iyz="0" izz="0.00417"/>
		</inertial>
		<visual>
			<origin rpy="0.00000 -0.00000 0.00000" xyz="0.00000 0.00000 0.25276"/>
			<geometry>
				<box size="0.05000 0.05000 0.45551"/>
			</geometry>
			<material name="mat_15_0">
				<color rgba="1.00000 1.00000 1.00000 1.00000" />
			</material>
		</visual>
		<collision>
			<origin rpy="0.00000 -0.00000 0.00000" xyz="0.00000 0.00000 0.25276"/>
			<geometry>
				<box size="0.05000 0.05000 0.45551"/>
			</geometry>
		</collision>
	</link>
	<link name="link17">
		<inertial>
			<origin rpy="0.00000 -0.00000 0.00000" xyz="0.00000 0.00000 0.00000"/>
			<mass value="0.00000"/>
			<inertia ixx="0.00000" ixy="0" ixz="0" iyy="0.00000" iyz="0" izz="0.00000"/>
		</inertial>
		<visual>
			<origin rpy="0.00000 -0.00000 0.00000" xyz="0.00000 0.00000 0.00000"/>
			<geometry>
				<box size="0.00000 0.00000 0.00000"/>
			</geometry>
			<material name="mat_16_0">
				<color rgba="1.00000 1.00000 1.00000 1.00000" />
			</material>
		</visual>
		<collision>
			<origin rpy="0.00000 -0.00000 0.00000" xyz="0.00000 0.00000 0.00000"/>
			<geometry>
				<box size="0.00000 0.00000 0.00000"/>
			</geometry>
		</collision>
	</link>
	<link name="link18">
		<inertial>
			<origin rpy="0.00000 -0.00000 0.00000" xyz="0.00000 0.00000 0.25000"/>
			<mass value="10.00000"/>
			<inertia ixx="0.14775" ixy="0" ixz="0" iyy="0.14775" iyz="0" izz="0.00417"/>
		</inertial>
		<visual>
			<origin rpy="0.00000 -0.00000 0.00000" xyz="0.00000 0.00000 0.23405"/>
			<geometry>
				<box size="0.05000 0.05000 0.41809"/>
			</geometry>
			<material name="mat_17_0">
				<color rgba="1.00000 1.00000 1.00000 1.00000" />
			</material>
		</visual>
		<collision>
			<origin rpy="0.00000 -0.00000 0.00000" xyz="0.00000 0.00000 0.23405"/>
			<geometry>
				<box size="0.05000 0.05000 0.41809"/>
			</geometry>
		</collision>
	</link>
	<joint name="joint1" type="continuous">
		<parent link="link0"/>
		<child link="link1"/>
		<dynamics damping="1.0" friction="0.0001"/>
		<origin rpy="0.00000 -0.00000 0.00000" xyz="0.00000 0.00000 0.01884"/>
		<axis xyz="1.00000 0.00000 0.00000"/>
	</joint>
	<joint name="joint2" type="continuous">
		<parent link="link1"/>
		<child link="link2"/>
		<dynamics damping="1.0" friction="0.0001"/>
		<origin rpy="0.00000 -0.00000 0.00000" xyz="0.00000 0.00000 0.00000"/>
		<axis xyz="0.00000 1.00000 0.00000"/>
	</joint>
	<joint name="joint3" type="continuous">
		<parent link="link2"/>
		<child link="link3"/>
		<dynamics damping="1.0" friction="0.0001"/>
		<origin rpy="-1.17892 0.00000 0.49289" xyz="0.04677 0.05000 0.43552"/>
		<axis xyz="1.00000 0.00000 0.00000"/>
	</joint>
	<joint name="joint4" type="continuous">
		<parent link="link3"/>
		<child link="link4"/>
		<dynamics damping="1.0" friction="0.0001"/>
		<origin rpy="0.00000 -0.00000 0.00000" xyz="0.00000 0.00000 0.00000"/>
		<axis xyz="0.00000 1.00000 0.00000"/>
	</joint>
	<joint name="joint5" type="continuous">
		<parent link="link4"/>
		<child link="link5"/>
		<dynamics damping="1.0" friction="0.0001"/>
		<origin rpy="0.00000 0.03540 0.00000" xyz="0.00000 0.00000 0.44877"/>
		<axis xyz="1.00000 0.00000 0.00000"/>
	</joint>
	<joint name="joint6" type="continuous">
		<parent link="link5"/>
		<child link="link6"/>
		<dynamics damping="1.0" friction="0.0001"/>
		<origin rpy="0.00000 -0.00000 0.00000" xyz="0.00000 0.00000 0.00000"/>
		<axis xyz="0.00000 1.00000 0.00000"/>
	</joint>
	<joint name="joint7" type="continuous">
		<parent link="link2"/>
		<child link="link7"/>
		<dynamics damping="1.0" friction="0.0001"/>
		<origin rpy="0.00000 -0.22869 0.22718" xyz="0.00000 0.00000 0.45776"/>
		<axis xyz="1.00000 0.00000 0.00000"/>
	</joint>
	<joint name="joint8" type="continuous">
		<parent link="link7"/>
		<child link="link8"/>
		<dynamics damping="1.0" friction="0.0001"/>
		<origin rpy="0.00000 -0.00000 0.00000" xyz="0.00000 0.00000 0.00000"/>
		<axis xyz="0.00000 1.00000 0.00000"/>
	</joint>
	<joint name="joint9" type="continuous">
		<parent link="link8"/>
		<child link="link9"/>
		<dynamics damping="1.0" friction="0.0001"/>
		<origin rpy="0.80203 -0.00000 -0.28776" xyz="0.02604 -0.05000 0.25859"/>
		<axis xyz="1.00000 0.00000 0.00000"/>
	</joint>
	<joint name="joint10" type="continuous">
		<parent link="link9"/>
		<child link="link10"/>
		<dynamics damping="1.0" friction="0.0001"/>
		<origin rpy="0.00000 -0.00000 0.00000" xyz="0.00000 0.00000 0.00000"/>
		<axis xyz="0.00000 1.00000 0.00000"/>
	</joint>
	<joint name="joint11" type="continuous">
		<parent link="link10"/>
		<child link="link11"/>
		<dynamics damping="1.0" friction="0.0001"/>
		<origin rpy="0.10226 -0.00000 0.00000" xyz="0.00000 0.00000 0.41246"/>
		<axis xyz="1.00000 0.00000 0.00000"/>
	</joint>
	<joint name="joint12" type="continuous">
		<parent link="link11"/>
		<child link="link12"/>
		<dynamics damping="1.0" friction="0.0001"/>
		<origin rpy="0.00000 -0.00000 0.00000" xyz="0.00000 0.00000 0.00000"/>
		<axis xyz="0.00000 1.00000 0.00000"/>
	</joint>
	<joint name="joint13" type="continuous">
		<parent link="link8"/>
		<child link="link13"/>
		<dynamics damping="1.0" friction="0.0001"/>
		<origin rpy="0.16537 0.00000 -0.27800" xyz="0.00000 0.00000 0.48473"/>
		<axis xyz="1.00000 0.00000 0.00000"/>
	</joint>
	<joint name="joint14" type="continuous">
		<parent link="link13"/>
		<child link="link14"/>
		<dynamics damping="1.0" friction="0.0001"/>
		<origin rpy="0.00000 -0.00000 0.00000" xyz="0.00000 0.00000 0.00000"/>
		<axis xyz="0.00000 1.00000 0.00000"/>
	</joint>
	<joint name="joint15" type="continuous">
		<parent link="link14"/>
		<child link="link15"/>
		<dynamics damping="1.0" friction="0.0001"/>
		<origin rpy="0.70002 0.00000 -0.32723" xyz="0.01556 -0.05000 0.28799"/>
		<axis xyz="1.00000 0.00000 0.00000"/>
	</joint>
	<joint name="joint16" type="continuous">
		<parent link="link15"/>
		<child link="link16"/>
		<dynamics damping="1.0" friction="0.0001"/>
		<origin rpy="0.00000 -0.00000 0.00000" xyz="0.00000 0.00000 0.00000"/>
		<axis xyz="0.00000 1.00000 0.00000"/>
	</joint>
	<joint name="joint17" type="continuous">
		<parent link="link16"/>
		<child link="link17"/>
		<dynamics damping="1.0" friction="0.0001"/>
		<origin rpy="-0.11000 0.00000 0.00000" xyz="0.00000 0.00000 0.48051"/>
		<axis xyz="1.00000 0.00000 0.00000"/>
	</joint>
	<joint name="joint18" type="continuous">
		<parent link="link17"/>
		<child link="link18"/>
		<dynamics damping="1.0" friction="0.0001"/>
		<origin rpy="0.00000 -0.00000 0.00000" xyz="0.00000 0.00000 0.00000"/>
		<axis xyz="0.00000 1.00000 0.00000"/>
	</joint>
</robot>
