<?xml version="0.0" ?>
<robot name="">
	<link name="link0">
		<inertial>
			<origin rpy="0.00000 -0.00000 0.00000" xyz="0.00000 0.00000 0.00000"/>
			<mass value="1000000000.00000"/>
			<inertia ixx="565362.31434" ixy="0" ixz="0" iyy="377887.38396" iyz="0" izz="509937.17263"/>
		</inertial>
		<visual>
			<origin rpy="0.00000 -0.00000 0.00000" xyz="0.00000 0.00000 0.00000"/>
			<geometry>
				<box size="0.04399 0.06469 0.05099"/>
			</geometry>
			<material name="mat_-1_0">
				<color rgba="1.00000 1.00000 1.00000 1.00000" />
			</material>
		</visual>
		<collision>
			<origin rpy="0.00000 -0.00000 0.00000" xyz="0.00000 0.00000 0.00000"/>
			<geometry>
				<box size="0.04399 0.06469 0.05099"/>
			</geometry>
		</collision>
	</link>
	<link name="link1">
		<inertial>
			<origin rpy="0.00000 -0.00000 0.00000" xyz="0.00000 0.00000 0.00000"/>
			<mass value="0.00000"/>
			<inertia ixx="0.00000" ixy="0" ixz="0" iyy="0.00000" iyz="0" izz="0.00000"/>
		</inertial>
		<visual>
			<origin rpy="0.00000 -0.00000 0.00000" xyz="0.00000 0.00000 0.00000"/>
			<geometry>
				<box size="0.00000 0.00000 0.00000"/>
			</geometry>
			<material name="mat_0_0">
				<color rgba="1.00000 1.00000 1.00000 1.00000" />
			</material>
		</visual>
		<collision>
			<origin rpy="0.00000 -0.00000 0.00000" xyz="0.00000 0.00000 0.00000"/>
			<geometry>
				<box size="0.00000 0.00000 0.00000"/>
			</geometry>
		</collision>
	</link>
	<link name="link2">
		<inertial>
			<origin rpy="0.00000 -0.00000 0.00000" xyz="0.00000 0.00000 0.25000"/>
			<mass value="10.00000"/>
			<inertia ixx="0.19830" ixy="0" ixz="0" iyy="0.19830" iyz="0" izz="0.00417"/>
		</inertial>
		<visual>
			<origin rpy="0.00000 -0.00000 0.00000" xyz="0.00000 0.00000 0.26762"/>
			<geometry>
				<box size="0.05000 0.05000 0.48525"/>
			</geometry>
			<material name="mat_1_0">
				<color rgba="1.00000 1.00000 1.00000 1.00000" />
			</material>
		</visual>
		<collision>
			<origin rpy="0.00000 -0.00000 0.00000" xyz="0.00000 0.00000 0.26762"/>
			<geometry>
				<box size="0.05000 0.05000 0.48525"/>
			</geometry>
		</collision>
	</link>
	<link name="link3">
		<inertial>
			<origin rpy="0.00000 -0.00000 0.00000" xyz="0.00000 0.00000 0.00000"/>
			<mass value="0.00000"/>
			<inertia ixx="0.00000" ixy="0" ixz="0" iyy="0.00000" iyz="0" izz="0.00000"/>
		</inertial>
		<visual>
			<origin rpy="0.00000 -0.00000 0.00000" xyz="0.00000 0.00000 0.00000"/>
			<geometry>
				<box size="0.00000 0.00000 0.00000"/>
			</geometry>
			<material name="mat_2_0">
				<color rgba="1.00000 1.00000 1.00000 1.00000" />
			</material>
		</visual>
		<collision>
			<origin rpy="0.00000 -0.00000 0.00000" xyz="0.00000 0.00000 0.00000"/>
			<geometry>
				<box size="0.00000 0.00000 0.00000"/>
			</geometry>
		</collision>
	</link>
	<link name="link4">
		<inertial>
			<origin rpy="0.00000 -0.00000 0.00000" xyz="0.00000 0.00000 0.25000"/>
			<mass value="10.00000"/>
			<inertia ixx="0.17005" ixy="0" ixz="0" iyy="0.17005" iyz="0" izz="0.00417"/>
		</inertial>
		<visual>
			<origin rpy="0.00000 -0.00000 0.00000" xyz="0.00000 0.00000 0.24948"/>
			<geometry>
				<box size="0.05000 0.05000 0.44895"/>
			</geometry>
			<material name="mat_3_0">
				<color rgba="1.00000 1.00000 1.00000 1.00000" />
			</material>
		</visual>
		<collision>
			<origin rpy="0.00000 -0.00000 0.00000" xyz="0.00000 0.00000 0.24948"/>
			<geometry>
				<box size="0.05000 0.05000 0.44895"/>
			</geometry>
		</collision>
	</link>
	<link name="link5">
		<inertial>
			<origin rpy="0.00000 -0.00000 0.00000" xyz="0.00000 0.00000 0.00000"/>
			<mass value="0.00000"/>
			<inertia ixx="0.00000" ixy="0" ixz="0" iyy="0.00000" iyz="0" izz="0.00000"/>
		</inertial>
		<visual>
			<origin rpy="0.00000 -0.00000 0.00000" xyz="0.00000 0.00000 0.00000"/>
			<geometry>
				<box size="0.00000 0.00000 0.00000"/>
			</geometry>
			<material name="mat_4_0">
				<color rgba="1.00000 1.00000 1.00000 1.00000" />
			</material>
		</visual>
		<collision>
			<origin rpy="0.00000 -0.00000 0.00000" xyz="0.00000 0.00000 0.00000"/>
			<geometry>
				<box size="0.00000 0.00000 0.00000"/>
			</geometry>
		</collision>
	</link>
	<link name="link6">
		<inertial>
			<origin rpy="0.00000 -0.00000 0.00000" xyz="0.00000 0.00000 0.25000"/>
			<mass value="10.00000"/>
			<inertia ixx="0.11169" ixy="0" ixz="0" iyy="0.11169" iyz="0" izz="0.00417"/>
		</inertial>
		<visual>
			<origin rpy="0.00000 -0.00000 0.00000" xyz="0.00000 0.00000 0.20634"/>
			<geometry>
				<box size="0.05000 0.05000 0.36267"/>
			</geometry>
			<material name="mat_5_0">
				<color rgba="1.00000 1.00000 1.00000 1.00000" />
			</material>
		</visual>
		<collision>
			<origin rpy="0.00000 -0.00000 0.00000" xyz="0.00000 0.00000 0.20634"/>
			<geometry>
				<box size="0.05000 0.05000 0.36267"/>
			</geometry>
		</collision>
	</link>
	<link name="link7">
		<inertial>
			<origin rpy="0.00000 -0.00000 0.00000" xyz="0.00000 0.00000 0.00000"/>
			<mass value="0.00000"/>
			<inertia ixx="0.00000" ixy="0" ixz="0" iyy="0.00000" iyz="0" izz="0.00000"/>
		</inertial>
		<visual>
			<origin rpy="0.00000 -0.00000 0.00000" xyz="0.00000 0.00000 0.00000"/>
			<geometry>
				<box size="0.00000 0.00000 0.00000"/>
			</geometry>
			<material name="mat_6_0">
				<color rgba="1.00000 1.00000 1.00000 1.00000" />
			</material>
		</visual>
		<collision>
			<origin rpy="0.00000 -0.00000 0.00000" xyz="0.00000 0.00000 0.00000"/>
			<geometry>
				<box size="0.00000 0.00000 0.00000"/>
			</geometry>
		</collision>
	</link>
	<link name="link8">
		<inertial>
			<origin rpy="0.00000 -0.00000 0.00000" xyz="0.00000 0.00000 0.25000"/>
			<mass value="10.00000"/>
			<inertia ixx="0.12468" ixy="0" ixz="0" iyy="0.12468" iyz="0" izz="0.00417"/>
		</inertial>
		<visual>
			<origin rpy="0.00000 -0.00000 0.00000" xyz="0.00000 0.00000 0.21678"/>
			<geometry>
				<box size="0.05000 0.05000 0.38356"/>
			</geometry>
			<material name="mat_7_0">
				<color rgba="1.00000 1.00000 1.00000 1.00000" />
			</material>
		</visual>
		<collision>
			<origin rpy="0.00000 -0.00000 0.00000" xyz="0.00000 0.00000 0.21678"/>
			<geometry>
				<box size="0.05000 0.05000 0.38356"/>
			</geometry>
		</collision>
	</link>
	<link name="link9">
		<inertial>
			<origin rpy="0.00000 -0.00000 0.00000" xyz="0.00000 0.00000 0.00000"/>
			<mass value="0.00000"/>
			<inertia ixx="0.00000" ixy="0" ixz="0" iyy="0.00000" iyz="0" izz="0.00000"/>
		</inertial>
		<visual>
			<origin rpy="0.00000 -0.00000 0.00000" xyz="0.00000 0.00000 0.00000"/>
			<geometry>
				<box size="0.00000 0.00000 0.00000"/>
			</geometry>
			<material name="mat_8_0">
				<color rgba="1.00000 1.00000 1.00000 1.00000" />
			</material>
		</visual>
		<collision>
			<origin rpy="0.00000 -0.00000 0.00000" xyz="0.00000 0.00000 0.00000"/>
			<geometry>
				<box size="0.00000 0.00000 0.00000"/>
			</geometry>
		</collision>
	</link>
	<link name="link10">
		<inertial>
			<origin rpy="0.00000 -0.00000 0.00000" xyz="0.00000 0.00000 0.25000"/>
			<mass value="10.00000"/>
			<inertia ixx="0.17904" ixy="0" ixz="0" iyy="0.17904" iyz="0" izz="0.00417"/>
		</inertial>
		<visual>
			<origin rpy="0.00000 -0.00000 0.00000" xyz="0.00000 0.00000 0.25541"/>
			<geometry>
				<box size="0.05000 0.05000 0.46082"/>
			</geometry>
			<material name="mat_9_0">
				<color rgba="1.00000 1.00000 1.00000 1.00000" />
			</material>
		</visual>
		<collision>
			<origin rpy="0.00000 -0.00000 0.00000" xyz="0.00000 0.00000 0.25541"/>
			<geometry>
				<box size="0.05000 0.05000 0.46082"/>
			</geometry>
		</collision>
	</link>
	<link name="link11">
		<inertial>
			<origin rpy="0.00000 -0.00000 0.00000" xyz="0.00000 0.00000 0.00000"/>
			<mass value="0.00000"/>
			<inertia ixx="0.00000" ixy="0" ixz="0" iyy="0.00000" iyz="0" izz="0.00000"/>
		</inertial>
		<visual>
			<origin rpy="0.00000 -0.00000 0.00000" xyz="0.00000 0.00000 0.00000"/>
			<geometry>
				<box size="0.00000 0.00000 0.00000"/>
			</geometry>
			<material name="mat_10_0">
				<color rgba="1.00000 1.00000 1.00000 1.00000" />
			</material>
		</visual>
		<collision>
			<origin rpy="0.00000 -0.00000 0.00000" xyz="0.00000 0.00000 0.00000"/>
			<geometry>
				<box size="0.00000 0.00000 0.00000"/>
			</geometry>
		</collision>
	</link>
	<link name="link12">
		<inertial>
			<origin rpy="0.00000 -0.00000 0.00000" xyz="0.00000 0.00000 0.25000"/>
			<mass value="10.00000"/>
			<inertia ixx="0.16672" ixy="0" ixz="0" iyy="0.16672" iyz="0" izz="0.00417"/>
		</inertial>
		<visual>
			<origin rpy="0.00000 -0.00000 0.00000" xyz="0.00000 0.00000 0.24724"/>
			<geometry>
				<box size="0.05000 0.05000 0.44449"/>
			</geometry>
			<material name="mat_11_0">
				<color rgba="1.00000 1.00000 1.00000 1.00000" />
			</material>
		</visual>
		<collision>
			<origin rpy="0.00000 -0.00000 0.00000" xyz="0.00000 0.00000 0.24724"/>
			<geometry>
				<box size="0.05000 0.05000 0.44449"/>
			</geometry>
		</collision>
	</link>
	<link name="link13">
		<inertial>
			<origin rpy="0.00000 -0.00000 0.00000" xyz="0.00000 0.00000 0.00000"/>
			<mass value="0.00000"/>
			<inertia ixx="0.00000" ixy="0" ixz="0" iyy="0.00000" iyz="0" izz="0.00000"/>
		</inertial>
		<visual>
			<origin rpy="0.00000 -0.00000 0.00000" xyz="0.00000 0.00000 0.00000"/>
			<geometry>
				<box size="0.00000 0.00000 0.00000"/>
			</geometry>
			<material name="mat_12_0">
				<color rgba="1.00000 1.00000 1.00000 1.00000" />
			</material>
		</visual>
		<collision>
			<origin rpy="0.00000 -0.00000 0.00000" xyz="0.00000 0.00000 0.00000"/>
			<geometry>
				<box size="0.00000 0.00000 0.00000"/>
			</geometry>
		</collision>
	</link>
	<link name="link14">
		<inertial>
			<origin rpy="0.00000 -0.00000 0.00000" xyz="0.00000 0.00000 0.25000"/>
			<mass value="10.00000"/>
			<inertia ixx="0.12643" ixy="0" ixz="0" iyy="0.12643" iyz="0" izz="0.00417"/>
		</inertial>
		<visual>
			<origin rpy="0.00000 -0.00000 0.00000" xyz="0.00000 0.00000 0.21814"/>
			<geometry>
				<box size="0.05000 0.05000 0.38628"/>
			</geometry>
			<material name="mat_13_0">
				<color rgba="1.00000 1.00000 1.00000 1.00000" />
			</material>
		</visual>
		<collision>
			<origin rpy="0.00000 -0.00000 0.00000" xyz="0.00000 0.00000 0.21814"/>
			<geometry>
				<box size="0.05000 0.05000 0.38628"/>
			</geometry>
		</collision>
	</link>
	<link name="link15">
		<inertial>
			<origin rpy="0.00000 -0.00000 0.00000" xyz="0.00000 0.00000 0.00000"/>
			<mass value="0.00000"/>
			<inertia ixx="0.00000" ixy="0" ixz="0" iyy="0.00000" iyz="0" izz="0.00000"/>
		</inertial>
		<visual>
			<origin rpy="0.00000 -0.00000 0.00000" xyz="0.00000 0.00000 0.00000"/>
			<geometry>
				<box size="0.00000 0.00000 0.00000"/>
			</geometry>
			<material name="mat_14_0">
				<color rgba="1.00000 1.00000 1.00000 1.00000" />
			</material>
		</visual>
		<collision>
			<origin rpy="0.00000 -0.00000 0.00000" xyz="0.00000 0.00000 0.00000"/>
			<geometry>
				<box size="0.00000 0.00000 0.00000"/>
			</geometry>
		</collision>
	</link>
	<link name="link16">
		<inertial>
			<origin rpy="0.00000 -0.00000 0.00000" xyz="0.00000 0.00000 0.25000"/>
			<mass value="10.00000"/>
			<inertia ixx="0.12548" ixy="0" ixz="0" iyy="0.12548" iyz="0" izz="0.00417"/>
		</inertial>
		<visual>
			<origin rpy="0.00000 -0.00000 0.00000" xyz="0.00000 0.00000 0.21740"/>
			<geometry>
				<box size="0.05000 0.05000 0.38480"/>
			</geometry>
			<material name="mat_15_0">
				<color rgba="1.00000 1.00000 1.00000 1.00000" />
			</material>
		</visual>
		<collision>
			<origin rpy="0.00000 -0.00000 0.00000" xyz="0.00000 0.00000 0.21740"/>
			<geometry>
				<box size="0.05000 0.05000 0.38480"/>
			</geometry>
		</collision>
	</link>
	<link name="link17">
		<inertial>
			<origin rpy="0.00000 -0.00000 0.00000" xyz="0.00000 0.00000 0.00000"/>
			<mass value="0.00000"/>
			<inertia ixx="0.00000" ixy="0" ixz="0" iyy="0.00000" iyz="0" izz="0.00000"/>
		</inertial>
		<visual>
			<origin rpy="0.00000 -0.00000 0.00000" xyz="0.00000 0.00000 0.00000"/>
			<geometry>
				<box size="0.00000 0.00000 0.00000"/>
			</geometry>
			<material name="mat_16_0">
				<color rgba="1.00000 1.00000 1.00000 1.00000" />
			</material>
		</visual>
		<collision>
			<origin rpy="0.00000 -0.00000 0.00000" xyz="0.00000 0.00000 0.00000"/>
			<geometry>
				<box size="0.00000 0.00000 0.00000"/>
			</geometry>
		</collision>
	</link>
	<link name="link18">
		<inertial>
			<origin rpy="0.00000 -0.00000 0.00000" xyz="0.00000 0.00000 0.25000"/>
			<mass value="10.00000"/>
			<inertia ixx="0.17315" ixy="0" ixz="0" iyy="0.17315" iyz="0" izz="0.00417"/>
		</inertial>
		<visual>
			<origin rpy="0.00000 -0.00000 0.00000" xyz="0.00000 0.00000 0.25154"/>
			<geometry>
				<box size="0.05000 0.05000 0.45308"/>
			</geometry>
			<material name="mat_17_0">
				<color rgba="1.00000 1.00000 1.00000 1.00000" />
			</material>
		</visual>
		<collision>
			<origin rpy="0.00000 -0.00000 0.00000" xyz="0.00000 0.00000 0.25154"/>
			<geometry>
				<box size="0.05000 0.05000 0.45308"/>
			</geometry>
		</collision>
	</link>
	<joint name="joint1" type="continuous">
		<parent link="link0"/>
		<child link="link1"/>
		<dynamics damping="1.0" friction="0.0001"/>
		<origin rpy="0.00000 -0.00000 0.00000" xyz="0.00000 0.00000 0.02549"/>
		<axis xyz="1.00000 0.00000 0.00000"/>
	</joint>
	<joint name="joint2" type="continuous">
		<parent link="link1"/>
		<child link="link2"/>
		<dynamics damping="1.0" friction="0.0001"/>
		<origin rpy="0.00000 -0.00000 0.00000" xyz="0.00000 0.00000 0.00000"/>
		<axis xyz="0.00000 1.00000 0.00000"/>
	</joint>
	<joint name="joint3" type="continuous">
		<parent link="link2"/>
		<child link="link3"/>
		<dynamics damping="1.0" friction="0.0001"/>
		<origin rpy="-1.26365 0.00000 0.38715" xyz="0.01760 0.05000 0.12688"/>
		<axis xyz="1.00000 0.00000 0.00000"/>
	</joint>
	<joint name="joint4" type="continuous">
		<parent link="link3"/>
		<child link="link4"/>
		<dynamics damping="1.0" friction="0.0001"/>
		<origin rpy="0.00000 -0.00000 0.00000" xyz="0.00000 0.00000 0.00000"/>
		<axis xyz="0.00000 1.00000 0.00000"/>
	</joint>
	<joint name="joint5" type="continuous">
		<parent link="link4"/>
		<child link="link5"/>
		<dynamics damping="1.0" friction="0.0001"/>
		<origin rpy="0.00000 -0.08901 0.00000" xyz="0.00000 0.00000 0.47395"/>
		<axis xyz="1.00000 0.00000 0.00000"/>
	</joint>
	<joint name="joint6" type="continuous">
		<parent link="link5"/>
		<child link="link6"/>
		<dynamics damping="1.0" friction="0.0001"/>
		<origin rpy="0.00000 -0.00000 0.00000" xyz="0.00000 0.00000 0.00000"/>
		<axis xyz="0.00000 1.00000 0.00000"/>
	</joint>
	<joint name="joint7" type="continuous">
		<parent link="link2"/>
		<child link="link7"/>
		<dynamics damping="1.0" friction="0.0001"/>
		<origin rpy="-0.00000 0.24068 -0.19072" xyz="0.00000 0.00000 0.51025"/>
		<axis xyz="1.00000 0.00000 0.00000"/>
	</joint>
	<joint name="joint8" type="continuous">
		<parent link="link7"/>
		<child link="link8"/>
		<dynamics damping="1.0" friction="0.0001"/>
		<origin rpy="0.00000 -0.00000 0.00000" xyz="0.00000 0.00000 0.00000"/>
		<axis xyz="0.00000 1.00000 0.00000"/>
	</joint>
	<joint name="joint9" type="continuous">
		<parent link="link8"/>
		<child link="link9"/>
		<dynamics damping="1.0" friction="0.0001"/>
		<origin rpy="0.98839 -0.00000 0.25530" xyz="0.01152 -0.05000 0.23060"/>
		<axis xyz="1.00000 0.00000 0.00000"/>
	</joint>
	<joint name="joint10" type="continuous">
		<parent link="link9"/>
		<child link="link10"/>
		<dynamics damping="1.0" friction="0.0001"/>
		<origin rpy="0.00000 -0.00000 0.00000" xyz="0.00000 0.00000 0.00000"/>
		<axis xyz="0.00000 1.00000 0.00000"/>
	</joint>
	<joint name="joint11" type="continuous">
		<parent link="link10"/>
		<child link="link11"/>
		<dynamics damping="1.0" friction="0.0001"/>
		<origin rpy="0.00000 -0.03065 0.00000" xyz="0.00000 0.00000 0.48582"/>
		<axis xyz="1.00000 0.00000 0.00000"/>
	</joint>
	<joint name="joint12" type="continuous">
		<parent link="link11"/>
		<child link="link12"/>
		<dynamics damping="1.0" friction="0.0001"/>
		<origin rpy="0.00000 -0.00000 0.00000" xyz="0.00000 0.00000 0.00000"/>
		<axis xyz="0.00000 1.00000 0.00000"/>
	</joint>
	<joint name="joint13" type="continuous">
		<parent link="link8"/>
		<child link="link13"/>
		<dynamics damping="1.0" friction="0.0001"/>
		<origin rpy="-0.08339 -0.00000 0.05278" xyz="0.00000 0.00000 0.40856"/>
		<axis xyz="1.00000 0.00000 0.00000"/>
	</joint>
	<joint name="joint14" type="continuous">
		<parent link="link13"/>
		<child link="link14"/>
		<dynamics damping="1.0" friction="0.0001"/>
		<origin rpy="0.00000 -0.00000 0.00000" xyz="0.00000 0.00000 0.00000"/>
		<axis xyz="0.00000 1.00000 0.00000"/>
	</joint>
	<joint name="joint15" type="continuous">
		<parent link="link14"/>
		<child link="link15"/>
		<dynamics damping="1.0" friction="0.0001"/>
		<origin rpy="-0.00000 -1.29226 0.07897" xyz="-0.05000 0.01202 0.38893"/>
		<axis xyz="1.00000 0.00000 0.00000"/>
	</joint>
	<joint name="joint16" type="continuous">
		<parent link="link15"/>
		<child link="link16"/>
		<dynamics damping="1.0" friction="0.0001"/>
		<origin rpy="0.00000 -0.00000 0.00000" xyz="0.00000 0.00000 0.00000"/>
		<axis xyz="0.00000 1.00000 0.00000"/>
	</joint>
	<joint name="joint17" type="continuous">
		<parent link="link16"/>
		<child link="link17"/>
		<dynamics damping="1.0" friction="0.0001"/>
		<origin rpy="0.06231 -0.00000 0.00000" xyz="0.00000 0.00000 0.40980"/>
		<axis xyz="1.00000 0.00000 0.00000"/>
	</joint>
	<joint name="joint18" type="continuous">
		<parent link="link17"/>
		<child link="link18"/>
		<dynamics damping="1.0" friction="0.0001"/>
		<origin rpy="0.00000 -0.00000 0.00000" xyz="0.00000 0.00000 0.00000"/>
		<axis xyz="0.00000 1.00000 0.00000"/>
	</joint>
</robot>
