<?xml version="0.0" ?>
<robot name="">
	<link name="link0">
		<inertial>
			<origin rpy="0.00000 -0.00000 0.00000" xyz="0.00000 0.00000 0.00000"/>
			<mass value="1000000000.00000"/>
			<inertia ixx="468828.61578" ixy="0" ixz="0" iyy="578595.49045" iyz="0" izz="642894.35415"/>
		</inertial>
		<visual>
			<origin rpy="0.00000 -0.00000 0.00000" xyz="0.00000 0.00000 0.00000"/>
			<geometry>
				<box size="0.06720 0.05656 0.04927"/>
			</geometry>
			<material name="mat_-1_0">
				<color rgba="1.00000 1.00000 1.00000 1.00000" />
			</material>
		</visual>
		<collision>
			<origin rpy="0.00000 -0.00000 0.00000" xyz="0.00000 0.00000 0.00000"/>
			<geometry>
				<box size="0.06720 0.05656 0.04927"/>
			</geometry>
		</collision>
	</link>
	<link name="link1">
		<inertial>
			<origin rpy="0.00000 -0.00000 0.00000" xyz="0.00000 0.00000 0.00000"/>
			<mass value="0.00000"/>
			<inertia ixx="0.00000" ixy="0" ixz="0" iyy="0.00000" iyz="0" izz="0.00000"/>
		</inertial>
		<visual>
			<origin rpy="0.00000 -0.00000 0.00000" xyz="0.00000 0.00000 0.00000"/>
			<geometry>
				<box size="0.00000 0.00000 0.00000"/>
			</geometry>
			<material name="mat_0_0">
				<color rgba="1.00000 1.00000 1.00000 1.00000" />
			</material>
		</visual>
		<collision>
			<origin rpy="0.00000 -0.00000 0.00000" xyz="0.00000 0.00000 0.00000"/>
			<geometry>
				<box size="0.00000 0.00000 0.00000"/>
			</geometry>
		</collision>
	</link>
	<link name="link2">
		<inertial>
			<origin rpy="0.00000 -0.00000 0.00000" xyz="0.00000 0.00000 0.25000"/>
			<mass value="10.00000"/>
			<inertia ixx="0.19584" ixy="0" ixz="0" iyy="0.19584" iyz="0" izz="0.00417"/>
		</inertial>
		<visual>
			<origin rpy="0.00000 -0.00000 0.00000" xyz="0.00000 0.00000 0.29110"/>
			<geometry>
				<box size="0.05000 0.05000 0.48220"/>
			</geometry>
			<material name="mat_1_0">
				<color rgba="1.00000 1.00000 1.00000 1.00000" />
			</material>
		</visual>
		<collision>
			<origin rpy="0.00000 -0.00000 0.00000" xyz="0.00000 0.00000 0.29110"/>
			<geometry>
				<box size="0.05000 0.05000 0.48220"/>
			</geometry>
		</collision>
	</link>
	<link name="link3">
		<inertial>
			<origin rpy="0.00000 -0.00000 0.00000" xyz="0.00000 0.00000 0.00000"/>
			<mass value="0.00000"/>
			<inertia ixx="0.00000" ixy="0" ixz="0" iyy="0.00000" iyz="0" izz="0.00000"/>
		</inertial>
		<visual>
			<origin rpy="0.00000 -0.00000 0.00000" xyz="0.00000 0.00000 0.00000"/>
			<geometry>
				<box size="0.00000 0.00000 0.00000"/>
			</geometry>
			<material name="mat_2_0">
				<color rgba="1.00000 1.00000 1.00000 1.00000" />
			</material>
		</visual>
		<collision>
			<origin rpy="0.00000 -0.00000 0.00000" xyz="0.00000 0.00000 0.00000"/>
			<geometry>
				<box size="0.00000 0.00000 0.00000"/>
			</geometry>
		</collision>
	</link>
	<link name="link4">
		<inertial>
			<origin rpy="0.00000 -0.00000 0.00000" xyz="0.00000 0.00000 0.25000"/>
			<mass value="10.00000"/>
			<inertia ixx="0.16907" ixy="0" ixz="0" iyy="0.16907" iyz="0" izz="0.00417"/>
		</inertial>
		<visual>
			<origin rpy="0.00000 -0.00000 0.00000" xyz="0.00000 0.00000 0.27382"/>
			<geometry>
				<box size="0.05000 0.05000 0.44764"/>
			</geometry>
			<material name="mat_3_0">
				<color rgba="1.00000 1.00000 1.00000 1.00000" />
			</material>
		</visual>
		<collision>
			<origin rpy="0.00000 -0.00000 0.00000" xyz="0.00000 0.00000 0.27382"/>
			<geometry>
				<box size="0.05000 0.05000 0.44764"/>
			</geometry>
		</collision>
	</link>
	<link name="link5">
		<inertial>
			<origin rpy="0.00000 -0.00000 0.00000" xyz="0.00000 0.00000 0.00000"/>
			<mass value="0.00000"/>
			<inertia ixx="0.00000" ixy="0" ixz="0" iyy="0.00000" iyz="0" izz="0.00000"/>
		</inertial>
		<visual>
			<origin rpy="0.00000 -0.00000 0.00000" xyz="0.00000 0.00000 0.00000"/>
			<geometry>
				<box size="0.00000 0.00000 0.00000"/>
			</geometry>
			<material name="mat_4_0">
				<color rgba="1.00000 1.00000 1.00000 1.00000" />
			</material>
		</visual>
		<collision>
			<origin rpy="0.00000 -0.00000 0.00000" xyz="0.00000 0.00000 0.00000"/>
			<geometry>
				<box size="0.00000 0.00000 0.00000"/>
			</geometry>
		</collision>
	</link>
	<link name="link6">
		<inertial>
			<origin rpy="0.00000 -0.00000 0.00000" xyz="0.00000 0.00000 0.25000"/>
			<mass value="10.00000"/>
			<inertia ixx="0.11734" ixy="0" ixz="0" iyy="0.11734" iyz="0" izz="0.00417"/>
		</inertial>
		<visual>
			<origin rpy="0.00000 -0.00000 0.00000" xyz="0.00000 0.00000 0.23595"/>
			<geometry>
				<box size="0.05000 0.05000 0.37190"/>
			</geometry>
			<material name="mat_5_0">
				<color rgba="1.00000 1.00000 1.00000 1.00000" />
			</material>
		</visual>
		<collision>
			<origin rpy="0.00000 -0.00000 0.00000" xyz="0.00000 0.00000 0.23595"/>
			<geometry>
				<box size="0.05000 0.05000 0.37190"/>
			</geometry>
		</collision>
	</link>
	<link name="link7">
		<inertial>
			<origin rpy="0.00000 -0.00000 0.00000" xyz="0.00000 0.00000 0.00000"/>
			<mass value="0.00000"/>
			<inertia ixx="0.00000" ixy="0" ixz="0" iyy="0.00000" iyz="0" izz="0.00000"/>
		</inertial>
		<visual>
			<origin rpy="0.00000 -0.00000 0.00000" xyz="0.00000 0.00000 0.00000"/>
			<geometry>
				<box size="0.00000 0.00000 0.00000"/>
			</geometry>
			<material name="mat_6_0">
				<color rgba="1.00000 1.00000 1.00000 1.00000" />
			</material>
		</visual>
		<collision>
			<origin rpy="0.00000 -0.00000 0.00000" xyz="0.00000 0.00000 0.00000"/>
			<geometry>
				<box size="0.00000 0.00000 0.00000"/>
			</geometry>
		</collision>
	</link>
	<link name="link8">
		<inertial>
			<origin rpy="0.00000 -0.00000 0.00000" xyz="0.00000 0.00000 0.25000"/>
			<mass value="10.00000"/>
			<inertia ixx="0.12855" ixy="0" ixz="0" iyy="0.12855" iyz="0" izz="0.00417"/>
		</inertial>
		<visual>
			<origin rpy="0.00000 -0.00000 0.00000" xyz="0.00000 0.00000 0.24478"/>
			<geometry>
				<box size="0.05000 0.05000 0.38956"/>
			</geometry>
			<material name="mat_7_0">
				<color rgba="1.00000 1.00000 1.00000 1.00000" />
			</material>
		</visual>
		<collision>
			<origin rpy="0.00000 -0.00000 0.00000" xyz="0.00000 0.00000 0.24478"/>
			<geometry>
				<box size="0.05000 0.05000 0.38956"/>
			</geometry>
		</collision>
	</link>
	<link name="link9">
		<inertial>
			<origin rpy="0.00000 -0.00000 0.00000" xyz="0.00000 0.00000 0.00000"/>
			<mass value="0.00000"/>
			<inertia ixx="0.00000" ixy="0" ixz="0" iyy="0.00000" iyz="0" izz="0.00000"/>
		</inertial>
		<visual>
			<origin rpy="0.00000 -0.00000 0.00000" xyz="0.00000 0.00000 0.00000"/>
			<geometry>
				<box size="0.00000 0.00000 0.00000"/>
			</geometry>
			<material name="mat_8_0">
				<color rgba="1.00000 1.00000 1.00000 1.00000" />
			</material>
		</visual>
		<collision>
			<origin rpy="0.00000 -0.00000 0.00000" xyz="0.00000 0.00000 0.00000"/>
			<geometry>
				<box size="0.00000 0.00000 0.00000"/>
			</geometry>
		</collision>
	</link>
	<link name="link10">
		<inertial>
			<origin rpy="0.00000 -0.00000 0.00000" xyz="0.00000 0.00000 0.25000"/>
			<mass value="10.00000"/>
			<inertia ixx="0.13393" ixy="0" ixz="0" iyy="0.13393" iyz="0" izz="0.00417"/>
		</inertial>
		<visual>
			<origin rpy="0.00000 -0.00000 0.00000" xyz="0.00000 0.00000 0.24889"/>
			<geometry>
				<box size="0.05000 0.05000 0.39777"/>
			</geometry>
			<material name="mat_9_0">
				<color rgba="1.00000 1.00000 1.00000 1.00000" />
			</material>
		</visual>
		<collision>
			<origin rpy="0.00000 -0.00000 0.00000" xyz="0.00000 0.00000 0.24889"/>
			<geometry>
				<box size="0.05000 0.05000 0.39777"/>
			</geometry>
		</collision>
	</link>
	<link name="link11">
		<inertial>
			<origin rpy="0.00000 -0.00000 0.00000" xyz="0.00000 0.00000 0.00000"/>
			<mass value="0.00000"/>
			<inertia ixx="0.00000" ixy="0" ixz="0" iyy="0.00000" iyz="0" izz="0.00000"/>
		</inertial>
		<visual>
			<origin rpy="0.00000 -0.00000 0.00000" xyz="0.00000 0.00000 0.00000"/>
			<geometry>
				<box size="0.00000 0.00000 0.00000"/>
			</geometry>
			<material name="mat_10_0">
				<color rgba="1.00000 1.00000 1.00000 1.00000" />
			</material>
		</visual>
		<collision>
			<origin rpy="0.00000 -0.00000 0.00000" xyz="0.00000 0.00000 0.00000"/>
			<geometry>
				<box size="0.00000 0.00000 0.00000"/>
			</geometry>
		</collision>
	</link>
	<link name="link12">
		<inertial>
			<origin rpy="0.00000 -0.00000 0.00000" xyz="0.00000 0.00000 0.25000"/>
			<mass value="10.00000"/>
			<inertia ixx="0.16387" ixy="0" ixz="0" iyy="0.16387" iyz="0" izz="0.00417"/>
		</inertial>
		<visual>
			<origin rpy="0.00000 -0.00000 0.00000" xyz="0.00000 0.00000 0.27031"/>
			<geometry>
				<box size="0.05000 0.05000 0.44062"/>
			</geometry>
			<material name="mat_11_0">
				<color rgba="1.00000 1.00000 1.00000 1.00000" />
			</material>
		</visual>
		<collision>
			<origin rpy="0.00000 -0.00000 0.00000" xyz="0.00000 0.00000 0.27031"/>
			<geometry>
				<box size="0.05000 0.05000 0.44062"/>
			</geometry>
		</collision>
	</link>
	<joint name="joint1" type="continuous">
		<parent link="link0"/>
		<child link="link1"/>
		<dynamics damping="1.0" friction="0.0001"/>
		<origin rpy="0.00000 -0.00000 0.00000" xyz="0.00000 0.00000 0.02463"/>
		<axis xyz="1.00000 0.00000 0.00000"/>
	</joint>
	<joint name="joint2" type="continuous">
		<parent link="link1"/>
		<child link="link2"/>
		<dynamics damping="1.0" friction="0.0001"/>
		<origin rpy="0.00000 -0.00000 0.00000" xyz="0.00000 0.00000 0.00000"/>
		<axis xyz="0.00000 1.00000 0.00000"/>
	</joint>
	<joint name="joint3" type="continuous">
		<parent link="link2"/>
		<child link="link3"/>
		<dynamics damping="1.0" friction="0.0001"/>
		<origin rpy="-0.00000 1.15218 -0.04656" xyz="0.05000 0.02824 0.36887"/>
		<axis xyz="1.00000 0.00000 0.00000"/>
	</joint>
	<joint name="joint4" type="continuous">
		<parent link="link3"/>
		<child link="link4"/>
		<dynamics damping="1.0" friction="0.0001"/>
		<origin rpy="0.00000 -0.00000 0.00000" xyz="0.00000 0.00000 0.00000"/>
		<axis xyz="0.00000 1.00000 0.00000"/>
	</joint>
	<joint name="joint5" type="continuous">
		<parent link="link4"/>
		<child link="link5"/>
		<dynamics damping="1.0" friction="0.0001"/>
		<origin rpy="0.01353 -0.00000 0.00000" xyz="0.00000 0.00000 0.49764"/>
		<axis xyz="1.00000 0.00000 0.00000"/>
	</joint>
	<joint name="joint6" type="continuous">
		<parent link="link5"/>
		<child link="link6"/>
		<dynamics damping="1.0" friction="0.0001"/>
		<origin rpy="0.00000 -0.00000 0.00000" xyz="0.00000 0.00000 0.00000"/>
		<axis xyz="0.00000 1.00000 0.00000"/>
	</joint>
	<joint name="joint7" type="continuous">
		<parent link="link2"/>
		<child link="link7"/>
		<dynamics damping="1.0" friction="0.0001"/>
		<origin rpy="0.00000 -0.17250 -0.08036" xyz="0.00000 0.00000 0.53220"/>
		<axis xyz="1.00000 0.00000 0.00000"/>
	</joint>
	<joint name="joint8" type="continuous">
		<parent link="link7"/>
		<child link="link8"/>
		<dynamics damping="1.0" friction="0.0001"/>
		<origin rpy="0.00000 -0.00000 0.00000" xyz="0.00000 0.00000 0.00000"/>
		<axis xyz="0.00000 1.00000 0.00000"/>
	</joint>
	<joint name="joint9" type="continuous">
		<parent link="link8"/>
		<child link="link9"/>
		<dynamics damping="1.0" friction="0.0001"/>
		<origin rpy="0.85499 -0.00000 -0.42213" xyz="0.01103 -0.05000 0.18030"/>
		<axis xyz="1.00000 0.00000 0.00000"/>
	</joint>
	<joint name="joint10" type="continuous">
		<parent link="link9"/>
		<child link="link10"/>
		<dynamics damping="1.0" friction="0.0001"/>
		<origin rpy="0.00000 -0.00000 0.00000" xyz="0.00000 0.00000 0.00000"/>
		<axis xyz="0.00000 1.00000 0.00000"/>
	</joint>
	<joint name="joint11" type="continuous">
		<parent link="link10"/>
		<child link="link11"/>
		<dynamics damping="1.0" friction="0.0001"/>
		<origin rpy="-0.07714 0.00000 0.00000" xyz="0.00000 0.00000 0.44777"/>
		<axis xyz="1.00000 0.00000 0.00000"/>
	</joint>
	<joint name="joint12" type="continuous">
		<parent link="link11"/>
		<child link="link12"/>
		<dynamics damping="1.0" friction="0.0001"/>
		<origin rpy="0.00000 -0.00000 0.00000" xyz="0.00000 0.00000 0.00000"/>
		<axis xyz="0.00000 1.00000 0.00000"/>
	</joint>
</robot>
