<?xml version="1.0"?>
<robot name="origins">
  <link name="base_link">
    <visual>
      <geometry>
        <box size="0.07 0.07 0.1"/>
      </geometry>
    </visual>
    <collision>
      <geometry>
        <box size="0.07 0.07 0.1"/>
      </geometry>
      <origin rpy = "0 0 0" xyz = "0 0 0"/>
    </collision>
    <inertial>
      <mass value="10000"/>
      <inertia ixx="1.0" ixy="0.0" ixz="0.0" iyy="1.0" iyz="0.0" izz="1.0"/>
    </inertial>
  </link>

  <link name="plant">
    <inertial>
      <origin rpy="0 0 0" xyz="0 0 0.3"/>
      <mass value="0.0"/>
      <inertia ixx="1" ixy="0" ixz="0" iyy="1" iyz="0" izz="1"/>
    </inertial>
    <visual>
      <geometry>
        <box size="0.05 0.05 1.2"/>
      </geometry>
      <origin rpy="0 0 0" xyz="0 0 0.6"/>
    </visual>
    <collision>
      <geometry>
        <box size="0.05 0.05 1.2"/>
      </geometry>
      <origin rpy="0 0 0" xyz="0 0 0.6"/>
    </collision>
  </link>

  <link name = "v1">
        <inertial>
			<origin rpy="0.00000 0.00000 0.00000" xyz="0.00000 0.00000 0.00000"/>
			<mass value="0.00000"/>
			<inertia ixx="0.00000" ixy="0" ixz="0" iyy="0.00000" iyz="0" izz="0.00000"/>
		</inertial>
    <visual>
      <geometry>
        <box size="0 0 0"/>
      </geometry>
      <origin rpy="0 0 0" xyz="0 0 0"/>
    </visual>
    <collision>
      <geometry>
        <box size="0 0 0"/>
      </geometry>
      <origin rpy="0 0 0" xyz="0 0 0"/>
    </collision>
  </link>


  <joint name="rot_y" type="revolute">
    <parent link="base_link"/>
    <child link="v1"/>
    <mass value="0.0"/>
<!--    RAISED_HEIGHT of the plant (along z axis)-->
    <origin xyz="0 0 0.10" rpy="0 0 0"/>
    <axis xyz = "0 1 0"/>
    <dynamics damping="10" friction="0"/>
    <limit effort="100" lower="-1.571" upper="1.571" velocity="10"/>
  </joint>

  <joint name="rot_x" type="revolute">
    <parent link="v1"/>
    <child link="plant"/>
    <mass value="0.0"/>
    <origin xyz="0 0 0.0" rpy="0 0 0"/>
    <axis xyz = "1 0 0"/>
    <dynamics damping="10" friction="0"/>
    <limit effort="100" lower="-1.571" upper="1.571" velocity="10"/>
  </joint>



  

</robot>